<robot name="tr1">
	<link name="base_link">
		<visual>
			<geometry>
        <mesh filename="package://tr1_description/meshes/base.dae" scale="0.1 0.1 0.1"/>
			</geometry>
			<origin rpy="0 0 3.1415" xyz="0.31 0.435 -0.1115"/>
		</visual>
	</link>

	<link name="body_link">
		<visual>
			<geometry>
        <mesh filename="package://tr1_description/meshes/body.dae" scale="0.1 0.1 0.1"/>
			</geometry>
			<origin rpy="0 0 0" xyz="-0.3975 -0.195 -0.038"/>
		</visual>
	</link>

	<link name="arm1_link">
		<visual>
			<geometry>
        <mesh filename="package://tr1_description/meshes/arm1.dae" scale="0.1 0.1 0.1"/>
			</geometry>
			<origin rpy="1.5708 0 0" xyz="-0.11 0 -0.14"/>
		</visual>
	</link>

	<link name="arm2_link">
		<visual>
			<geometry>
        <mesh filename="package://tr1_description/meshes/arm2.dae" scale="0.1 0.1 0.1"/>
			</geometry>
			<origin rpy="1.5708 0 0.01" xyz="-0.110 0.0 -0.130"/>
		</visual>
	</link>

	<link name="arm3_link">
		<visual>
			<geometry>
        <mesh filename="package://tr1_description/meshes/arm3.dae" scale="0.1 0.1 0.1"/>
			</geometry>
			<origin rpy="0 0 0" xyz="0 0 0"/>
		</visual>
	</link>

	<link name="arm4_link">
		<visual>
			<geometry>
        <mesh filename="package://tr1_description/meshes/arm4.dae" scale="0.1 0.1 0.1"/>
			</geometry>
			<origin rpy="0 0 0" xyz="0 0 0"/>
		</visual>
	</link>

	<link name="arm5_link">
		<visual>
			<geometry>
        <mesh filename="package://tr1_description/meshes/arm5.dae" scale="0.1 0.1 0.1"/>
			</geometry>
			<origin rpy="0 0 0" xyz="0 0 0"/>
		</visual>
	</link>

	<link name="arm6_link">
		<visual>
			<geometry>
        <mesh filename="package://tr1_description/meshes/arm6.dae" scale="0.1 0.1 0.1"/>
			</geometry>
			<origin rpy="0 0 0" xyz="0 0 0"/>
		</visual>
	</link>

	<link name="arm7_link">
		<visual>
			<geometry>
        <mesh filename="package://tr1_description/meshes/arm7.dae" scale="0.1 0.1 0.1"/>
			</geometry>
			<origin rpy="0 0 0" xyz="0 0 0"/>
		</visual>
	</link>

	<link name="arm8_link">
		<visual>
			<geometry>
        <mesh filename="package://tr1_description/meshes/arm8.dae" scale="0.1 0.1 0.1"/>
			</geometry>
			<origin rpy="0 0 0" xyz="0 0 0"/>
		</visual>
	</link>

	<link name="neck_base_link">
		<visual>
			<geometry>
        <mesh filename="package://tr1_description/meshes/neck_base.dae" scale="0.1 0.1 0.1"/>
			</geometry>
			<origin rpy="1.5708 0 0" xyz="0 0.095 -0.023"/>
		</visual>
	</link>

	<link name="neck_link">
		<visual>
			<geometry>
        <mesh filename="package://tr1_description/meshes/neck.dae" scale="0.1 0.1 0.1"/>
			</geometry>
			<origin rpy="1.5708 0 0" xyz="0 0.096 -0.055"/>
		</visual>
	</link>

	<link name="head_link">
		<visual>
			<geometry>
        <mesh filename="package://tr1_description/meshes/head.dae" scale="0.1 0.1 0.1"/>
			</geometry>
			<origin rpy="1.8326 0 0" xyz="0 0.0434 -0.139"/>
		</visual>
	</link>

	<joint name="base_to_body" type="prismatic">
		<parent link="base_link"/>
		<child link="body_link"/>
    <axis xyz="0 0 1"/>
		<limit effort="1000.0" lower="0" upper="0.300" velocity="0.0001"/>
		<origin rpy="0 0 0" xyz="0 0 0.7955"/>
	</joint>

	<joint name="body_to_arm1" type="fixed">
		<parent link="body_link"/>
		<child link="arm1_link"/>
		<origin rpy="0 0 0.261799" xyz="0.184864 0.034420 0.2075"/>
	</joint>

	<joint name="arm1_to_arm2" type="revolute">
		<parent link="arm1_link"/>
		<child link="arm2_link"/>
		<origin rpy="0 0 0" xyz="0 0 -0.007"/>
    <axis xyz="0 0 1"/>
		<limit effort="1.0" lower="-1" upper="1.5708" velocity="0.5"/>
	</joint>

	<joint name="arm2_to_arm3" type="revolute">
		<parent link="arm2_link"/>
		<child link="arm3_link"/>
		<origin rpy="0 0 0" xyz="0.139238 0 0"/>
    <axis xyz="0 1 0"/>
		<limit effort="1.0" lower="-1" upper="1.5708" velocity="0.5"/>
	</joint>

	<joint name="arm3_to_arm4" type="fixed">
		<parent link="arm3_link"/>
		<child link="arm4_link"/>
		<origin rpy="0 0 0" xyz="0 0 0"/>
	</joint>

	<joint name="arm4_to_arm5" type="fixed">
		<parent link="arm4_link"/>
		<child link="arm5_link"/>
		<origin rpy="0 0 0" xyz="0 0 0"/>
	</joint>

	<joint name="arm5_to_arm6" type="fixed">
		<parent link="arm5_link"/>
		<child link="arm6_link"/>
		<origin rpy="0 0 0" xyz="0 0 0"/>
	</joint>

	<joint name="arm6_to_arm7" type="fixed">
		<parent link="arm6_link"/>
		<child link="arm7_link"/>
		<origin rpy="0 0 0" xyz="0 0 0"/>
	</joint>

	<joint name="arm7_to_arm8" type="fixed">
		<parent link="arm7_link"/>
		<child link="arm8_link"/>
		<origin rpy="0 0 0" xyz="0 0 0"/>
	</joint>

	<joint name="body_to_neck_base" type="fixed">
		<parent link="body_link"/>
		<child link="neck_base_link"/>
		<origin rpy="0 0 0" xyz="0 -0.017 0.365"/>
	</joint>

	<joint name="neck_base_to_neck" type="revolute">
		<parent link="neck_base_link"/>
		<child link="neck_link"/>
		<origin rpy="0 0 0" xyz="0 0 0.033"/>
    <axis xyz="0 0 1"/>
		<limit effort="1.0" lower="-3.1415" upper="3.1415" velocity="0.5"/>
	</joint>

	<joint name="neck_to_head" type="revolute">
		<parent link="neck_link"/>
		<child link="head_link"/>
		<origin rpy="0 0 0" xyz="0 0.090789 0.09"/>
    <axis xyz="1 0 0"/>
		<limit effort="1.0" lower="-0.9" upper="0.4" velocity="0.5"/>
	</joint>

</robot>
