<robot name="tr1">
	<link name="base_link">
		<visual>
			<geometry>
        <mesh filename="package://tr1_description/meshes/base.dae" scale="0.1 0.1 0.1"/>
			</geometry>
			<origin rpy="0 0 3.1415" xyz="0.31 0.4595 -0.1115"/>
		</visual>
	</link>

	<link name="body_link">
		<visual>
			<geometry>
        <mesh filename="package://tr1_description/meshes/body.dae" scale="0.1 0.1 0.1"/>
			</geometry>
			<origin rpy="0 0 0" xyz="-0.3975 -0.17 -0.038"/>
		</visual>
	</link>

	<link name="arm1_link">
		<visual>
			<geometry>
        <mesh filename="package://tr1_description/meshes/arm1.dae" scale="0.1 0.1 0.1"/>
			</geometry>
			<origin rpy="1.5708 0 0" xyz="-0.073 0.0238 -0.14"/>
		</visual>
	</link>

	<link name="neck_base_link">
		<visual>
			<geometry>
        <mesh filename="package://tr1_description/meshes/neck_base.dae" scale="0.1 0.1 0.1"/>
			</geometry>
			<origin rpy="1.57 0 0" xyz="0 0.103 -0.023"/>
		</visual>
	</link>

	<link name="neck_link">
		<visual>
			<geometry>
        <mesh filename="package://tr1_description/meshes/neck.dae" scale="0.1 0.1 0.1"/>
			</geometry>
			<origin rpy="1.57 0 0" xyz="0 0.096 -0.055"/>
		</visual>
	</link>

	<link name="head_link">
		<visual>
			<geometry>
        <mesh filename="package://tr1_description/meshes/head.dae" scale="0.1 0.1 0.1"/>
			</geometry>
			<origin rpy="1.8326 0 0" xyz="0 0.0434 -0.139"/>
		</visual>
	</link>

	<joint name="base_to_body" type="prismatic">
		<parent link="base_link"/>
		<child link="body_link"/>
    <axis xyz="0 0 1"/>
		<limit effort="1000.0" lower="0" upper="0.300" velocity="0.0001"/>
		<origin rpy="0 0 0" xyz="0 0 0.7955"/>
	</joint>

	<joint name="body_to_arm1" type="fixed">
		<parent link="body_link"/>
		<child link="arm1_link"/>
		<origin rpy="0 0 0.261799" xyz="0.155887 0.026656 0.2075"/>
	</joint>

	<joint name="body_to_neck_base" type="fixed">
		<parent link="body_link"/>
		<child link="neck_base_link"/>
		<origin rpy="0 0 0" xyz="0 0 0.365"/>
	</joint>

	<joint name="neck_base_to_neck" type="revolute">
		<parent link="neck_base_link"/>
		<child link="neck_link"/>
		<origin rpy="0 0 0" xyz="0 0 0.033"/>
    <axis xyz="0 0 1"/>
		<limit effort="1.0" lower="-3.1415" upper="3.1415" velocity="0.5"/>
	</joint>

	<joint name="neck_to_head" type="revolute">
		<parent link="neck_link"/>
		<child link="head_link"/>
		<origin rpy="0 0 0" xyz="0 0.090789 0.09"/>
    <axis xyz="1 0 0"/>
		<limit effort="1.0" lower="-0.9" upper="0.4" velocity="0.5"/>
	</joint>

</robot>
