<robot name="tr1">
	<link name="base_link">
		<visual>
			<geometry>
        <mesh filename="package://tr1_description/meshes/base.dae" scale="0.1 0.1 0.1"/>
			</geometry>
			<origin rpy="0 0 3.1415" xyz="0.31 0.5095 -0.1115"/>
		</visual>
	</link>
	<link name="body_link">
		<visual>
			<geometry>
        <mesh filename="package://tr1_description/meshes/body.dae" scale="0.1 0.1 0.1"/>
			</geometry>
			<origin rpy="0 0 0" xyz="-0.3975 -0.12 0"/>
		</visual>
	</link>
	<joint name="base_to_body" type="prismatic">
		<parent link="base_link"/>
		<child link="body_link"/>
		<limit effort="1000.0" lower="0" upper="150" velocity="0.5"/>
		<origin rpy="0 0 0" xyz="0 0 0.8"/>
	</joint>
</robot>
