<robot name="tr1">

	<link name="base_link">
		<visual>
			<geometry>
        <mesh filename="package://tr1_description/meshes/dae/base.dae" scale="0.001 0.001 0.001"/>
			</geometry>
			<origin rpy="0 0 3.141592" />
		</visual>
	</link>

	<link name="wheel1_link">
		<visual>
			<geometry>
        <mesh filename="package://tr1_description/meshes/dae/wheel.dae" scale="0.001 0.001 0.001"/>
			</geometry>
			<origin rpy="1.5708 0 0" />
		</visual>
	</link>

	<link name="wheel2_link">
		<visual>
			<geometry>
        <mesh filename="package://tr1_description/meshes/dae/wheel.dae" scale="0.001 0.001 0.001"/>
			</geometry>
			<origin rpy="1.5708 0 0" />
		</visual>
	</link>

	<link name="wheel3_link">
		<visual>
			<geometry>
        <mesh filename="package://tr1_description/meshes/dae/wheel.dae" scale="0.001 0.001 0.001"/>
			</geometry>
			<origin rpy="1.5708 0 0" />
		</visual>
	</link>

	<link name="wheel4_link">
		<visual>
			<geometry>
        <mesh filename="package://tr1_description/meshes/dae/wheel.dae" scale="0.001 0.001 0.001"/>
			</geometry>
			<origin rpy="1.5708 0 0" />
		</visual>
	</link>

	<link name="body_link">
		<visual>
			<geometry>
        <mesh filename="package://tr1_description/meshes/dae/body.dae" scale="0.001 0.001 0.001"/>
			</geometry>
			<origin rpy="0 0 3.141592"/>
		</visual>
	</link>

	<link name="arm1_link">
		<visual>
			<geometry>
        <mesh filename="package://tr1_description/meshes/dae/arm1.dae" scale="0.001 0.001 0.001"/>
			</geometry>
			<origin rpy="1.5708 0 0" />
		</visual>
	</link>

	<link name="arm2_link">
		<visual>
			<geometry>
        <mesh filename="package://tr1_description/meshes/dae/arm2.dae" scale="0.001 0.001 0.001"/>
			</geometry>
			<origin rpy="1.5708 0 0" />
		</visual>
	</link>

	<joint name="base_to_body" type="prismatic">
		<parent link="base_link"/>
		<child link="body_link"/>
    <axis xyz="0 0 1"/>
		<limit effort="1000.0" lower="0" upper="0.300" velocity="0.0001"/>
		<origin xyz="0 0 0.7955"/>
	</joint>

	<joint name="base_to_wheel1" type="continuous">
		<parent link="base_link"/>
		<child link="wheel1_link"/>
    <axis xyz="0 1 0"/>
		<origin rpy="0 0 0.785398" xyz="-0.293310 0.417810 -0.0725"/>
	</joint>

	<joint name="base_to_wheel2" type="continuous">
		<parent link="base_link"/>
		<child link="wheel2_link"/>
    <axis xyz="0 1 0"/>
		<origin rpy="0 0 -0.785398" xyz="0.293310 0.417810 -0.0725"/>
	</joint>

	<joint name="base_to_wheel3" type="continuous">
		<parent link="base_link"/>
		<child link="wheel3_link"/>
    <axis xyz="0 1 0"/>
		<origin rpy="0 0 -2.35619449019" xyz="0.293310 -0.168810 -0.0725"/>
	</joint>

	<joint name="base_to_wheel4" type="continuous">
		<parent link="base_link"/>
		<child link="wheel4_link"/>
    <axis xyz="0 1 0"/>
		<origin rpy="0 0 2.356194490191" xyz="-0.293310 -0.168810 -0.0725"/>
	</joint>

	<joint name="body_to_arm1" type="fixed">
		<parent link="body_link"/>
		<child link="arm1_link"/>
		<origin rpy="0 0 0.261799" xyz="0.184864 0.034420 0.20575"/>
	</joint>

	<joint name="arm1_to_arm2" type="revolute">
		<parent link="arm1_link"/>
		<child link="arm2_link"/>
		<origin xyz="0 0 -0.007"/>
    <axis xyz="0 0 1"/>
		<limit effort="1.0" lower="-1" upper="1.5708" velocity="0.5"/>
	</joint>

</robot>
